Workbook

Sheet Зведена_аптеки
A3: Позначки рядків | B3: Сума з сума_чеку
A4: Аптека №2 | B4: 451712.3
A5: Аптека №7 | B5: 410703.18
A6: Аптека №18 | B6: 377655.99
A7: Аптека №4 | B7: 375106.1
A8: Аптека №5 | B8: 371141.53
A9: Аптека №21 | B9: 369613.64
A10: Аптека №60 | B10: 361691.51
A11: Аптека №30 | B11: 356601.57
A12: Аптека №14 | B12: 355189.94
A13: Аптека №23 | B13: 355022.67
A14: Аптека №22 | B14: 352571.79
A15: Аптека №37 | B15: 348050.91
... A64: Загальний підсумок | B64: 18367273

Sheet Працівник_аналіз
A1: {=_xlfn.UNIQUE(Продаж!F:F)} -> id_працівника | B1: К_сть продажів | C1: Загальна_виручка | D1: Загальна_к_сть_відпрацьованих год | E1: Загальна_к_сть_змін | F1: Загальна к_сть_перепрацьованих змін | G1: Загальна к_сть_перепрацьованих_год | H1: Перепрацьовані_год | I1: Загальна_к_сть недопрацьованих змін | J1: Загальна_к_сть недопрацьованих год | K1: Недопрацьовані год | L1: Середній_дохід_за_год
A2: 15 | B2: =COUNTIF(Продаж!F:F,Працівник_аналіз!A2) -> 14 | C2: =SUMIF(Продаж!F:F,Працівник_аналіз!A2,Продаж!I:I) -> 48670.23 | D2: =SUMIF(Робота!B:B,Працівник_аналіз!A2,Робота!D:D) -> 259 | E2: =COUNTIF(Робота!B:B,Працівник_аналіз!A2) -> 31 | F2: =COUNTIFS(Робота!B:B,Працівник_аналіз!A2,Робота!D:D,">8") -> 14 | G2: =SUMIFS(Робота!D:D,Робота!B:B,Працівник_аналіз!A2,Робота!D:D,">8") -> 148 | H2: =G2-(F2*8) -> 36 | I2: =COUNTIFS(Робота!B:B,Працівник_аналіз!A2,Робота!D:D,"<8") -> 14 | J2: =SUMIFS(Робота!D:D,Робота!B:B,Працівник_аналіз!A2,Робота!D:D,"<8") -> 87 | K2: =(I2*8)-J2 -> 25 | L2: =C2/D2 -> 187.91595
A3: 101 | B3: =COUNTIF(Продаж!F:F,Працівник_аналіз!A3) -> 9 | C3: =SUMIF(Продаж!F:F,Працівник_аналіз!A3,Продаж!I:I) -> 37434.66 | D3: =SUMIF(Робота!B:B,Працівник_аналіз!A3,Робота!D:D) -> 214 | E3: =COUNTIF(Робота!B:B,Працівник_аналіз!A3) -> 27 | F3: =COUNTIFS(Робота!B:B,Працівник_аналіз!A3,Робота!D:D,">8") -> 9 | G3: =SUMIFS(Робота!D:D,Робота!B:B,Працівник_аналіз!A3,Робота!D:D,">8") -> 100 | H3: =G3-(F3*8) -> 28 | I3: =COUNTIFS(Робота!B:B,Працівник_аналіз!A3,Робота!D:D,"<8") -> 13 | J3: =SUMIFS(Робота!D:D,Робота!B:B,Працівник_аналіз!A3,Робота!D:D,"<8") -> 74 | K3: =(I3*8)-J3 -> 30 | L3: =C3/D3 -> 174.92832
A4: 133 | B4: =COUNTIF(Продаж!F:F,Працівник_аналіз!A4) -> 8 | C4: =SUMIF(Продаж!F:F,Працівник_аналіз!A4,Продаж!I:I) -> 20745.51 | D4: =SUMIF(Робота!B:B,Працівник_аналіз!A4,Робота!D:D) -> 166 | E4: =COUNTIF(Робота!B:B,Працівник_аналіз!A4) -> 22 | F4: =COUNTIFS(Робота!B:B,Працівник_аналіз!A4,Робота!D:D,">8") -> 8 | G4: =SUMIFS(Робота!D:D,Робота!B:B,Працівник_аналіз!A4,Робота!D:D,">8") -> 87 | H4: =G4-(F4*8) -> 23 | I4: =COUNTIFS(Робота!B:B,Працівник_аналіз!A4,Робота!D:D,"<8") -> 13 | J4: =SUMIFS(Робота!D:D,Робота!B:B,Працівник_аналіз!A4,Робота!D:D,"<8") -> 71 | K4: =(I4*8)-J4 -> 33 | L4: =C4/D4 -> 124.97295
A5: 16 | B5: =COUNTIF(Продаж!F:F,Працівник_аналіз!A5) -> 15 | C5: =SUMIF(Продаж!F:F,Працівник_аналіз!A5,Продаж!I:I) -> 56802.08 | D5: =SUMIF(Робота!B:B,Працівник_аналіз!A5,Робота!D:D) -> 219 | E5: =COUNTIF(Робота!B:B,Працівник_аналіз!A5) -> 29 | F5: =COUNTIFS(Робота!B:B,Працівник_аналіз!A5,Робота!D:D,">8") -> 10 | G5: =SUMIFS(Робота!D:D,Робота!B:B,Працівник_аналіз!A5,Робота!D:D,">8") -> 100 | H5: =G5-(F5*8) -> 20 | I5: =COUNTIFS(Робота!B:B,Працівник_аналіз!A5,Робота!D:D,"<8") -> 13 | J5: =SUMIFS(Робота!D:D,Робота!B:B,Працівник_аналіз!A5,Робота!D:D,"<8") -> 71 | K5: =(I5*8)-J5 -> 33 | L5: =C5/D5 -> 259.37023
A6: 48 | B6: =COUNTIF(Продаж!F:F,Працівник_аналіз!A6) -> 17 | C6: =SUMIF(Продаж!F:F,Працівник_аналіз!A6,Продаж!I:I) -> 40543.72 | D6: =SUMIF(Робота!B:B,Працівник_аналіз!A6,Робота!D:D) -> 219 | E6: =COUNTIF(Робота!B:B,Працівник_аналіз!A6) -> 25 | F6: =COUNTIFS(Робота!B:B,Працівник_аналіз!A6,Робота!D:D,">8") -> 15 | G6: =SUMIFS(Робота!D:D,Робота!B:B,Працівник_аналіз!A6,Робота!D:D,">8") -> 162 | H6: =G6-(F6*8) -> 42 | I6: =COUNTIFS(Робота!B:B,Працівник_аналіз!A6,Робота!D:D,"<8") -> 8 | J6: =SUMIFS(Робота!D:D,Робота!B:B,Працівник_аналіз!A6,Робота!D:D,"<8") -> 41 | K6: =(I6*8)-J6 -> 23 | L6: =C6/D6 -> 185.13114
A7: 61 | B7: =COUNTIF(Продаж!F:F,Працівник_аналіз!A7) -> 10 | C7: =SUMIF(Продаж!F:F,Працівник_аналіз!A7,Продаж!I:I) -> 36192.13 | D7: =SUMIF(Робота!B:B,Працівник_аналіз!A7,Робота!D:D) -> 156 | E7: =COUNTIF(Робота!B:B,Працівник_аналіз!A7) -> 19 | F7: =COUNTIFS(Робота!B:B,Працівник_аналіз!A7,Робота!D:D,">8") -> 7 | G7: =SUMIFS(Робота!D:D,Робота!B:B,Працівник_аналіз!A7,Робота!D:D,">8") -> 73 | H7: =G7-(F7*8) -> 17 | I7: =COUNTIFS(Робота!B:B,Працівник_аналіз!A7,Робота!D:D,"<8") -> 5 | J7: =SUMIFS(Робота!D:D,Робота!B:B,Працівник_аналіз!A7,Робота!D:D,"<8") -> 27 | K7: =(I7*8)-J7 -> 13 | L7: =C7/D7 -> 232.00083
A8: 221 | B8: =COUNTIF(Продаж!F:F,Працівник_аналіз!A8) -> 19 | C8: =SUMIF(Продаж!F:F,Працівник_аналіз!A8,Продаж!I:I) -> 80297.01 | D8: =SUMIF(Робота!B:B,Працівник_аналіз!A8,Робота!D:D) -> 180 | E8: =COUNTIF(Робота!B:B,Працівник_аналіз!A8) -> 22 | F8: =COUNTIFS(Робота!B:B,Працівник_аналіз!A8,Робота!D:D,">8") -> 9 | G8: =SUMIFS(Робота!D:D,Робота!B:B,Працівник_аналіз!A8,Робота!D:D,">8") -> 100 | H8: =G8-(F8*8) -> 28 | I8: =COUNTIFS(Робота!B:B,Працівник_аналіз!A8,Робота!D:D,"<8") -> 8 | J8: =SUMIFS(Робота!D:D,Робота!B:B,Працівник_аналіз!A8,Робота!D:D,"<8") -> 40 | K8: =(I8*8)-J8 -> 24 | L8: =C8/D8 -> 446.0945
A9: 160 | B9: =COUNTIF(Продаж!F:F,Працівник_аналіз!A9) -> 13 | C9: =SUMIF(Продаж!F:F,Працівник_аналіз!A9,Продаж!I:I) -> 40069.45 | D9: =SUMIF(Робота!B:B,Працівник_аналіз!A9,Робота!D:D) -> 233 | E9: =COUNTIF(Робота!B:B,Працівник_аналіз!A9) -> 26 | F9: =COUNTIFS(Робота!B:B,Працівник_аналіз!A9,Робота!D:D,">8") -> 18 | G9: =SUMIFS(Робота!D:D,Робота!B:B,Працівник_аналіз!A9,Робота!D:D,">8") -> 188 | H9: =G9-(F9*8) -> 44 | I9: =COUNTIFS(Робота!B:B,Працівник_аналіз!A9,Робота!D:D,"<8") -> 8 | J9: =SUMIFS(Робота!D:D,Робота!B:B,Працівник_аналіз!A9,Робота!D:D,"<8") -> 45 | K9: =(I9*8)-J9 -> 19 | L9: =C9/D9 -> 171.97189
A10: 304 | B10: =COUNTIF(Продаж!F:F,Працівник_аналіз!A10) -> 15 | C10: =SUMIF(Продаж!F:F,Працівник_аналіз!A10,Продаж!I:I) -> 69382.46 | D10: =SUMIF(Робота!B:B,Працівник_аналіз!A10,Робота!D:D) -> 172 | E10: =COUNTIF(Робота!B:B,Працівник_аналіз!A10) -> 21 | F10: =COUNTIFS(Робота!B:B,Працівник_аналіз!A10,Робота!D:D,">8") -> 11 | G10: =SUMIFS(Робота!D:D,Робота!B:B,Працівник_аналіз!A10,Робота!D:D,">8") -> 112 | H10: =G10-(F10*8) -> 24 | I10: =COUNTIFS(Робота!B:B,Працівник_аналіз!A10,Робота!D:D,"<8") -> 8 | J10: =SUMIFS(Робота!D:D,Робота!B:B,Працівник_аналіз!A10,Робота!D:D,"<8") -> 44 | K10: =(I10*8)-J10 -> 20 | L10: =C10/D10 -> 403.3864
A11: 346 | B11: =COUNTIF(Продаж!F:F,Працівник_аналіз!A11) -> 15 | C11: =SUMIF(Продаж!F:F,Працівник_аналіз!A11,Продаж!I:I) -> 53762.05 | D11: =SUMIF(Робота!B:B,Працівник_аналіз!A11,Робота!D:D) -> 196 | E11: =COUNTIF(Робота!B:B,Працівник_аналіз!A11) -> 27 | F11: =COUNTIFS(Робота!B:B,Працівник_аналіз!A11,Робота!D:D,">8") -> 6 | G11: =SUMIFS(Робота!D:D,Робота!B:B,Працівник_аналіз!A11,Робота!D:D,">8") -> 66 | H11: =G11-(F11*8) -> 18 | I11: =COUNTIFS(Робота!B:B,Працівник_аналіз!A11,Робота!D:D,"<8") -> 17 | J11: =SUMIFS(Робота!D:D,Робота!B:B,Працівник_аналіз!A11,Робота!D:D,"<8") -> 98 | K11: =(I11*8)-J11 -> 38 | L11: =C11/D11 -> 274.29617
A12: 45 | B12: =COUNTIF(Продаж!F:F,Працівник_аналіз!A12) -> 22 | C12: =SUMIF(Продаж!F:F,Працівник_аналіз!A12,Продаж!I:I) -> 89531.15 | D12: =SUMIF(Робота!B:B,Працівник_аналіз!A12,Робота!D:D) -> 189 | E12: =COUNTIF(Робота!B:B,Працівник_аналіз!A12) -> 23 | F12: =COUNTIFS(Робота!B:B,Працівник_аналіз!A12,Робота!D:D,">8") -> 10 | G12: =SUMIFS(Робота!D:D,Робота!B:B,Працівник_аналіз!A12,Робота!D:D,">8") -> 106 | H12: =G12-(F12*8) -> 26 | I12: =COUNTIFS(Робота!B:B,Працівник_аналіз!A12,Робота!D:D,"<8") -> 9 | J12: =SUMIFS(Робота!D:D,Робота!B:B,Працівник_аналіз!A12,Робота!D:D,"<8") -> 51 | K12: =(I12*8)-J12 -> 21 | L12: =C12/D12 -> 473.70979
A13: 124 | B13: =COUNTIF(Продаж!F:F,Працівник_аналіз!A13) -> 13 | C13: =SUMIF(Продаж!F:F,Працівник_аналіз!A13,Продаж!I:I) -> 45328.79 | D13: =SUMIF(Робота!B:B,Працівник_аналіз!A13,Робота!D:D) -> 231 | E13: =COUNTIF(Робота!B:B,Працівник_аналіз!A13) -> 28 | F13: =COUNTIFS(Робота!B:B,Працівник_аналіз!A13,Робота!D:D,">8") -> 11 | G13: =SUMIFS(Робота!D:D,Робота!B:B,Працівник_аналіз!A13,Робота!D:D,">8") -> 123 | H13: =G13-(F13*8) -> 35 | I13: =COUNTIFS(Робота!B:B,Працівник_аналіз!A13,Робота!D:D,"<8") -> 12 | J13: =SUMIFS(Робота!D:D,Робота!B:B,Працівник_аналіз!A13,Робота!D:D,"<8") -> 68 | K13: =(I13*8)-J13 -> 28 | L13: =C13/D13 -> 196.22853
... A402: 0 | B402: =COUNTIF(Продаж!F:F,Працівник_аналіз!A402) -> 0 | C402: =SUMIF(Продаж!F:F,Працівник_аналіз!A402,Продаж!I:I) -> 0 | D402: =SUMIF(Робота!B:B,Працівник_аналіз!A402,Робота!D:D) -> 0 | E402: =COUNTIF(Робота!B:B,Працівник_аналіз!A402) -> 0 | F402: =COUNTIFS(Робота!B:B,Працівник_аналіз!A402,Робота!D:D,">8") -> 0 | G402: =SUMIFS(Робота!D:D,Робота!B:B,Працівник_аналіз!A402,Робота!D:D,">8") -> 0 | H402: =G402-(F402*8) -> 0 | I402: =COUNTIFS(Робота!B:B,Працівник_аналіз!A402,Робота!D:D,"<8") -> 0 | J402: =SUMIFS(Робота!D:D,Робота!B:B,Працівник_аналіз!A402,Робота!D:D,"<8") -> 0 | K402: =(I402*8)-J402 -> 0 | L402: =C402/D402 -> #DIV/0!

Sheet Зведена прац
A3: Позначки рядків | B3: Кількість з id_продажу | C3: Сума з сума_чеку
A4: 1 | B4: 13 | C4: 57347.11
A5: 2 | B5: 13 | C5: 42852.77
A6: 3 | B6: 16 | C6: 57896.67
A7: 4 | B7: 22 | C7: 83052.16
A8: 5 | B8: 13 | C8: 54334.06
A9: 6 | B9: 12 | C9: 40781.08
A10: 7 | B10: 13 | C10: 64578.78
A11: 8 | B11: 10 | C11: 40151.74
A12: 9 | B12: 16 | C12: 66107.32
A13: 10 | B13: 19 | C13: 61132.57
A14: 11 | B14: 8 | C14: 34314.34
A15: 12 | B15: 13 | C15: 44205.07
... A403: 400 | B403: 20 | C403: 64533.18
A404: Загальний підсумок | B404: 5000 | C404: 18367273

Sheet Зведена_покупець
A3: Позначки рядків | B3: Сума для сума_чеку | C3: Підрахунок для id_продажу | D3: Середнє значення сума_чеку2
A4: (пусто) | B4: 5608482.5 | C4: 1472 | D4: 3810.1104
A5: 335 | B5: 56053.65 | C5: 14 | D5: 4003.8321
A6: 39 | B6: 52184.9 | C6: 11 | D6: 4744.0818
A7: 130 | B7: 51733.95 | C7: 13 | D7: 3979.5346
A8: 394 | B8: 51292.83 | C8: 12 | D8: 4274.4025
A9: 228 | B9: 51165.2 | C9: 11 | D9: 4651.3818
A10: 289 | B10: 51162.34 | C10: 11 | D10: 4651.1218
A11: 355 | B11: 50062.54 | C11: 13 | D11: 3850.9646
A12: 399 | B12: 49738.42 | C12: 14 | D12: 3552.7443
A13: 537 | B13: 48786.82 | C13: 10 | D13: 4878.682
A14: 404 | B14: 47740.52 | C14: 13 | D14: 3672.3477
A15: 188 | B15: 47671.26 | C15: 10 | D15: 4767.126
A16: 235 | B16: 47444.02 | C16: 10 | D16: 4744.402
... A568: 452 | B568: 804.11 | C568: 1 | D568: 804.11
A569: Загальний підсумок | B569: 18367273 | C569: 5000 | D569: 3673.4546

Sheet Тип_продажу
A3: Позначки рядків | B3: Сума для сума_чеку
A4: є рецепт | B4: 5414766.3
A5: нема рецепту | B5: 12952507
A6: Загальний підсумок | B6: 18367273

Sheet Продаж
A1: id_продажу | B1: дата_час | C1: тип_оплати | D1: id_аптеки | E1: id_покупця | F1: id_працівника | G1: id_рецепту | H1: id_чеку | I1: сума_чеку | J1: назва_аптеки | K1: тип_продажу | M1: к_сть_без_рецепту | N1: к_сть_з_рецептом
A2: 1 | B2: 45678 | C2: готівка | D2: 15 | E2: 437 | F2: 15 | H2: 1001 | I2: =SUMIF(Чек_позиція!D:D,Продаж!H2,Чек_позиція!F:F) -> 4149.26 | J2: =VLOOKUP(D2,Аптека!A:B,2,FALSE) -> Аптека №15 | K2: =IF(G2="", "нема рецепту","є рецепт") -> нема рецепту | M2: =COUNTIF(K:K,K2) -> 3547 | N2: =COUNTIF(K:K,K5) -> 1453
A3: 2 | B3: 45730 | C3: готівка | D3: 41 | E3: 240 | F3: 101 | H3: 1002 | I3: =SUMIF(Чек_позиція!D:D,Продаж!H3,Чек_позиція!F:F) -> 6886.05 | J3: =VLOOKUP(D3,Аптека!A:B,2,FALSE) -> Аптека №41 | K3: =IF(G3="", "нема рецепту","є рецепт") -> нема рецепту
A4: 3 | B4: 45771 | C4: готівка | D4: 13 | E4: 449 | F4: 133 | H4: 1003 | I4: =SUMIF(Чек_позиція!D:D,Продаж!H4,Чек_позиція!F:F) -> 2848.84 | J4: =VLOOKUP(D4,Аптека!A:B,2,FALSE) -> Аптека №13 | K4: =IF(G4="", "нема рецепту","є рецепт") -> нема рецепту
A5: 4 | B5: 45811 | C5: готівка | D5: 16 | E5: 341 | F5: 16 | G5: 916 | H5: 1004 | I5: =SUMIF(Чек_позиція!D:D,Продаж!H5,Чек_позиція!F:F) -> 4680.23 | J5: =VLOOKUP(D5,Аптека!A:B,2,FALSE) -> Аптека №16 | K5: =IF(G5="", "нема рецепту","є рецепт") -> є рецепт
A6: 5 | B6: 45778 | C6: карта | D6: 48 | F6: 48 | G6: 872 | H6: 1005 | I6: =SUMIF(Чек_позиція!D:D,Продаж!H6,Чек_позиція!F:F) -> 3275.16 | J6: =VLOOKUP(D6,Аптека!A:B,2,FALSE) -> Аптека №48 | K6: =IF(G6="", "нема рецепту","є рецепт") -> є рецепт
A7: 6 | B7: 45834 | C7: карта | D7: 1 | F7: 61 | G7: 763 | H7: 1006 | I7: =SUMIF(Чек_позиція!D:D,Продаж!H7,Чек_позиція!F:F) -> 3124.08 | J7: =VLOOKUP(D7,Аптека!A:B,2,FALSE) -> Аптека №1 | K7: =IF(G7="", "нема рецепту","є рецепт") -> є рецепт
A8: 7 | B8: 45793 | C8: карта | D8: 41 | F8: 221 | H8: 1007 | I8: =SUMIF(Чек_позиція!D:D,Продаж!H8,Чек_позиція!F:F) -> 7543.3 | J8: =VLOOKUP(D8,Аптека!A:B,2,FALSE) -> Аптека №41 | K8: =IF(G8="", "нема рецепту","є рецепт") -> нема рецепту
A9: 8 | B9: 45779 | C9: карта | D9: 40 | E9: 124 | F9: 160 | H9: 1008 | I9: =SUMIF(Чек_позиція!D:D,Продаж!H9,Чек_позиція!F:F) -> 6639.22 | J9: =VLOOKUP(D9,Аптека!A:B,2,FALSE) -> Аптека №40 | K9: =IF(G9="", "нема рецепту","є рецепт") -> нема рецепту
A10: 9 | B10: 45708 | C10: карта | D10: 4 | E10: 318 | F10: 304 | H10: 1009 | I10: =SUMIF(Чек_позиція!D:D,Продаж!H10,Чек_позиція!F:F) -> 5243.51 | J10: =VLOOKUP(D10,Аптека!A:B,2,FALSE) -> Аптека №4 | K10: =IF(G10="", "нема рецепту","є рецепт") -> нема рецепту
A11: 10 | B11: 45714 | C11: готівка | D11: 46 | F11: 346 | G11: 851 | H11: 1010 | I11: =SUMIF(Чек_позиція!D:D,Продаж!H11,Чек_позиція!F:F) -> 2320.98 | J11: =VLOOKUP(D11,Аптека!A:B,2,FALSE) -> Аптека №46 | K11: =IF(G11="", "нема рецепту","є рецепт") -> є рецепт
A12: 11 | B12: 45710 | C12: карта | D12: 45 | F12: 45 | H12: 1011 | I12: =SUMIF(Чек_позиція!D:D,Продаж!H12,Чек_позиція!F:F) -> 2620.18 | J12: =VLOOKUP(D12,Аптека!A:B,2,FALSE) -> Аптека №45 | K12: =IF(G12="", "нема рецепту","є рецепт") -> нема рецепту
A13: 12 | B13: 45690 | C13: карта | D13: 4 | F13: 124 | H13: 1012 | I13: =SUMIF(Чек_позиція!D:D,Продаж!H13,Чек_позиція!F:F) -> 7363.18 | J13: =VLOOKUP(D13,Аптека!A:B,2,FALSE) -> Аптека №4 | K13: =IF(G13="", "нема рецепту","є рецепт") -> нема рецепту
A14: 13 | B14: 45801 | C14: карта | D14: 28 | E14: 367 | F14: 268 | G14: 254 | H14: 1013 | I14: =SUMIF(Чек_позиція!D:D,Продаж!H14,Чек_позиція!F:F) -> 6417.2 | J14: =VLOOKUP(D14,Аптека!A:B,2,FALSE) -> Аптека №28 | K14: =IF(G14="", "нема рецепту","є рецепт") -> є рецепт
A15: 14 | B15: 45815 | C15: карта | D15: 16 | E15: 274 | F15: 256 | H15: 1014 | I15: =SUMIF(Чек_позиція!D:D,Продаж!H15,Чек_позиція!F:F) -> 956.28 | J15: =VLOOKUP(D15,Аптека!A:B,2,FALSE) -> Аптека №16 | K15: =IF(G15="", "нема рецепту","є рецепт") -> нема рецепту
A16: 15 | B16: 45813 | C16: карта | D16: 5 | E16: 373 | F16: 125 | H16: 1015 | I16: =SUMIF(Чек_позиція!D:D,Продаж!H16,Чек_позиція!F:F) -> 1435.23 | J16: =VLOOKUP(D16,Аптека!A:B,2,FALSE) -> Аптека №5 | K16: =IF(G16="", "нема рецепту","є рецепт") -> нема рецепту
A17: 16 | B17: 45739 | C17: готівка | D17: 41 | E17: 50 | F17: 161 | H17: 1016 | I17: =SUMIF(Чек_позиція!D:D,Продаж!H17,Чек_позиція!F:F) -> 2641.96 | J17: =VLOOKUP(D17,Аптека!A:B,2,FALSE) -> Аптека №41 | K17: =IF(G17="", "нема рецепту","є рецепт") -> нема рецепту
A18: 17 | B18: 45781 | C18: готівка | D18: 25 | E18: 135 | F18: 25 | H18: 1017 | I18: =SUMIF(Чек_позиція!D:D,Продаж!H18,Чек_позиція!F:F) -> 478.65 | J18: =VLOOKUP(D18,Аптека!A:B,2,FALSE) -> Аптека №25 | K18: =IF(G18="", "нема рецепту","є рецепт") -> нема рецепту
A19: 18 | B19: 45797 | C19: готівка | D19: 35 | F19: 275 | H19: 1018 | I19: =SUMIF(Чек_позиція!D:D,Продаж!H19,Чек_позиція!F:F) -> 4271.45 | J19: =VLOOKUP(D19,Аптека!A:B,2,FALSE) -> Аптека №35 | K19: =IF(G19="", "нема рецепту","є рецепт") -> нема рецепту
A20: 19 | B20: 45684 | C20: карта | D20: 13 | F20: 13 | G20: 488 | H20: 1019 | I20: =SUMIF(Чек_позиція!D:D,Продаж!H20,Чек_позиція!F:F) -> 698.64 | J20: =VLOOKUP(D20,Аптека!A:B,2,FALSE) -> Аптека №13 | K20: =IF(G20="", "нема рецепту","є рецепт") -> є рецепт
A21: 20 | B21: 45838 | C21: готівка | D21: 46 | E21: 81 | F21: 286 | H21: 1020 | I21: =SUMIF(Чек_позиція!D:D,Продаж!H21,Чек_позиція!F:F) -> 1183.9 | J21: =VLOOKUP(D21,Аптека!A:B,2,FALSE) -> Аптека №46 | K21: =IF(G21="", "нема рецепту","є рецепт") -> нема рецепту
A22: 21 | B22: 45682 | C22: карта | D22: 16 | F22: 256 | G22: 1093 | H22: 1021 | I22: =SUMIF(Чек_позиція!D:D,Продаж!H22,Чек_позиція!F:F) -> 6468.96 | J22: =VLOOKUP(D22,Аптека!A:B,2,FALSE) -> Аптека №16 | K22: =IF(G22="", "нема рецепту","є рецепт") -> є рецепт
A23: 22 | B23: 45743 | C23: карта | D23: 2 | F23: 182 | H23: 1022 | I23: =SUMIF(Чек_позиція!D:D,Продаж!H23,Чек_позиція!F:F) -> 4079.82 | J23: =VLOOKUP(D23,Аптека!A:B,2,FALSE) -> Аптека №2 | K23: =IF(G23="", "нема рецепту","є рецепт") -> нема рецепту
A24: 23 | B24: 45705 | C24: готівка | D24: 37 | E24: 16 | F24: 37 | H24: 1023 | I24: =SUMIF(Чек_позиція!D:D,Продаж!H24,Чек_позиція!F:F) -> 6960.66 | J24: =VLOOKUP(D24,Аптека!A:B,2,FALSE) -> Аптека №37 | K24: =IF(G24="", "нема рецепту","є рецепт") -> нема рецепту
A25: 24 | B25: 45814 | C25: карта | D25: 29 | E25: 454 | F25: 329 | H25: 1024 | I25: =SUMIF(Чек_позиція!D:D,Продаж!H25,Чек_позиція!F:F) -> 4423.79 | J25: =VLOOKUP(D25,Аптека!A:B,2,FALSE) -> Аптека №29 | K25: =IF(G25="", "нема рецепту","є рецепт") -> нема рецепту
A26: 25 | B26: 45755 | C26: карта | D26: 52 | E26: 15 | F26: 352 | G26: 435 | H26: 1025 | I26: =SUMIF(Чек_позиція!D:D,Продаж!H26,Чек_позиція!F:F) -> 6754.74 | J26: =VLOOKUP(D26,Аптека!A:B,2,FALSE) -> Аптека №52 | K26: =IF(G26="", "нема рецепту","є рецепт") -> є рецепт
A27: 26 | B27: 45818 | C27: готівка | D27: 53 | F27: 113 | H27: 1026 | I27: =SUMIF(Чек_позиція!D:D,Продаж!H27,Чек_позиція!F:F) -> 2388.83 | J27: =VLOOKUP(D27,Аптека!A:B,2,FALSE) -> Аптека №53 | K27: =IF(G27="", "нема рецепту","є рецепт") -> нема рецепту
A28: 27 | B28: 45676 | C28: карта | D28: 32 | E28: 48 | F28: 212 | G28: 147 | H28: 1027 | I28: =SUMIF(Чек_позиція!D:D,Продаж!H28,Чек_позиція!F:F) -> 4471.58 | J28: =VLOOKUP(D28,Аптека!A:B,2,FALSE) -> Аптека №32 | K28: =IF(G28="", "нема рецепту","є рецепт") -> є рецепт
A29: 28 | B29: 45730 | C29: готівка | D29: 19 | F29: 319 | H29: 1028 | I29: =SUMIF(Чек_позиція!D:D,Продаж!H29,Чек_позиція!F:F) -> 739.64 | J29: =VLOOKUP(D29,Аптека!A:B,2,FALSE) -> Аптека №19 | K29: =IF(G29="", "нема рецепту","є рецепт") -> нема рецепту
A30: 29 | B30: 45667 | C30: карта | D30: 2 | E30: 547 | F30: 2 | H30: 1029 | I30: =SUMIF(Чек_позиція!D:D,Продаж!H30,Чек_позиція!F:F) -> 1176.34 | J30: =VLOOKUP(D30,Аптека!A:B,2,FALSE) -> Аптека №2 | K30: =IF(G30="", "нема рецепту","є рецепт") -> нема рецепту
A31: 30 | B31: 45693 | C31: карта | D31: 24 | F31: 204 | H31: 1030 | I31: =SUMIF(Чек_позиція!D:D,Продаж!H31,Чек_позиція!F:F) -> 1993.44 | J31: =VLOOKUP(D31,Аптека!A:B,2,FALSE) -> Аптека №24 | K31: =IF(G31="", "нема рецепту","є рецепт") -> нема рецепту
A32: 31 | B32: 45732 | C32: карта | D32: 43 | E32: 105 | F32: 283 | H32: 1031 | I32: =SUMIF(Чек_позиція!D:D,Продаж!H32,Чек_позиція!F:F) -> 5233.51 | J32: =VLOOKUP(D32,Аптека!A:B,2,FALSE) -> Аптека №43 | K32: =IF(G32="", "нема рецепту","є рецепт") -> нема рецепту
A33: 32 | B33: 45832 | C33: карта | D33: 19 | E33: 126 | F33: 79 | G33: 37 | H33: 1032 | I33: =SUMIF(Чек_позиція!D:D,Продаж!H33,Чек_позиція!F:F) -> 1439.93 | J33: =VLOOKUP(D33,Аптека!A:B,2,FALSE) -> Аптека №19 | K33: =IF(G33="", "нема рецепту","є рецепт") -> є рецепт
A34: 33 | B34: 45688 | C34: карта | D34: 16 | F34: 316 | H34: 1033 | I34: =SUMIF(Чек_позиція!D:D,Продаж!H34,Чек_позиція!F:F) -> 5455.91 | J34: =VLOOKUP(D34,Аптека!A:B,2,FALSE) -> Аптека №16 | K34: =IF(G34="", "нема рецепту","є рецепт") -> нема рецепту
A35: 34 | B35: 45822 | C35: карта | D35: 53 | E35: 214 | F35: 53 | H35: 1034 | I35: =SUMIF(Чек_позиція!D:D,Продаж!H35,Чек_позиція!F:F) -> 1377 | J35: =VLOOKUP(D35,Аптека!A:B,2,FALSE) -> Аптека №53 | K35: =IF(G35="", "нема рецепту","є рецепт") -> нема рецепту
A36: 35 | B36: 45720 | C36: готівка | D36: 36 | E36: 107 | F36: 156 | H36: 1035 | I36: =SUMIF(Чек_позиція!D:D,Продаж!H36,Чек_позиція!F:F) -> 1918.85 | J36: =VLOOKUP(D36,Аптека!A:B,2,FALSE) -> Аптека №36 | K36: =IF(G36="", "нема рецепту","є рецепт") -> нема рецепту
A37: 36 | B37: 45808 | C37: карта | D37: 6 | F37: 66 | H37: 1036 | I37: =SUMIF(Чек_позиція!D:D,Продаж!H37,Чек_позиція!F:F) -> 5462.78 | J37: =VLOOKUP(D37,Аптека!A:B,2,FALSE) -> Аптека №6 | K37: =IF(G37="", "нема рецепту","є рецепт") -> нема рецепту
A38: 37 | B38: 45710 | C38: карта | D38: 39 | F38: 39 | H38: 1037 | I38: =SUMIF(Чек_позиція!D:D,Продаж!H38,Чек_позиція!F:F) -> 4138.6 | J38: =VLOOKUP(D38,Аптека!A:B,2,FALSE) -> Аптека №39 | K38: =IF(G38="", "нема рецепту","є рецепт") -> нема рецепту
A39: 38 | B39: 45688 | C39: карта | D39: 54 | E39: 368 | F39: 354 | H39: 1038 | I39: =SUMIF(Чек_позиція!D:D,Продаж!H39,Чек_позиція!F:F) -> 5339.51 | J39: =VLOOKUP(D39,Аптека!A:B,2,FALSE) -> Аптека №54 | K39: =IF(G39="", "нема рецепту","є рецепт") -> нема рецепту
A40: 39 | B40: 45717 | C40: готівка | D40: 13 | F40: 313 | H40: 1039 | I40: =SUMIF(Чек_позиція!D:D,Продаж!H40,Чек_позиція!F:F) -> 1280.74 | J40: =VLOOKUP(D40,Аптека!A:B,2,FALSE) -> Аптека №13 | K40: =IF(G40="", "нема рецепту","є рецепт") -> нема рецепту
...

Sheet Покупець_аналіз
A1: id_покупця | B1: прізвище | C1: ім'я | D1: вік | E1: К_сть_покупок | F1: Загальна_сума_витрат | G1: Середній_чек
A2: 1 | B2: Бондар | C2: Тетяна | D2: 67 | E2: =COUNTIF(Продаж!E:E,Покупець_аналіз!A2) -> 6 | F2: =SUMIF(Продаж!E:E,A2,Продаж!I:I) -> 13735.59 | G2: =AVERAGEIF(Продаж!E:E,Покупець_аналіз!A2,Продаж!I:I) -> 2289.265
A3: 2 | B3: Мельник | C3: Сергій | D3: 66 | E3: =COUNTIF(Продаж!E:E,Покупець_аналіз!A3) -> 7 | F3: =SUMIF(Продаж!E:E,A3,Продаж!I:I) -> 25450.89 | G3: =AVERAGEIF(Продаж!E:E,Покупець_аналіз!A3,Продаж!I:I) -> 3635.8414
A4: 3 | B4: Романюк | C4: Тетяна | D4: 84 | E4: =COUNTIF(Продаж!E:E,Покупець_аналіз!A4) -> 11 | F4: =SUMIF(Продаж!E:E,A4,Продаж!I:I) -> 28939.1 | G4: =AVERAGEIF(Продаж!E:E,Покупець_аналіз!A4,Продаж!I:I) -> 2630.8273
A5: 4 | B5: Степаненко | C5: Катерина | D5: 48 | E5: =COUNTIF(Продаж!E:E,Покупець_аналіз!A5) -> 7 | F5: =SUMIF(Продаж!E:E,A5,Продаж!I:I) -> 34599.27 | G5: =AVERAGEIF(Продаж!E:E,Покупець_аналіз!A5,Продаж!I:I) -> 4942.7529
A6: 5 | B6: Кушнір | C6: Дмитро | D6: 53 | E6: =COUNTIF(Продаж!E:E,Покупець_аналіз!A6) -> 7 | F6: =SUMIF(Продаж!E:E,A6,Продаж!I:I) -> 19540.53 | G6: =AVERAGEIF(Продаж!E:E,Покупець_аналіз!A6,Продаж!I:I) -> 2791.5043
A7: 6 | B7: Коваль | C7: Олександр | D7: 54 | E7: =COUNTIF(Продаж!E:E,Покупець_аналіз!A7) -> 10 | F7: =SUMIF(Продаж!E:E,A7,Продаж!I:I) -> 28790.51 | G7: =AVERAGEIF(Продаж!E:E,Покупець_аналіз!A7,Продаж!I:I) -> 2879.051
A8: 7 | B8: Коваль | C8: Руслан | D8: 39 | E8: =COUNTIF(Продаж!E:E,Покупець_аналіз!A8) -> 5 | F8: =SUMIF(Продаж!E:E,A8,Продаж!I:I) -> 11452.72 | G8: =AVERAGEIF(Продаж!E:E,Покупець_аналіз!A8,Продаж!I:I) -> 2290.544
A9: 8 | B9: Савчук | C9: Андрій | D9: 78 | E9: =COUNTIF(Продаж!E:E,Покупець_аналіз!A9) -> 8 | F9: =SUMIF(Продаж!E:E,A9,Продаж!I:I) -> 17739.49 | G9: =AVERAGEIF(Продаж!E:E,Покупець_аналіз!A9,Продаж!I:I) -> 2217.4362
A10: 9 | B10: Шевченко | C10: Максим | D10: 78 | E10: =COUNTIF(Продаж!E:E,Покупець_аналіз!A10) -> 6 | F10: =SUMIF(Продаж!E:E,A10,Продаж!I:I) -> 16443.7 | G10: =AVERAGEIF(Продаж!E:E,Покупець_аналіз!A10,Продаж!I:I) -> 2740.6167
A11: 10 | B11: Білан | C11: Софія | D11: 71 | E11: =COUNTIF(Продаж!E:E,Покупець_аналіз!A11) -> 8 | F11: =SUMIF(Продаж!E:E,A11,Продаж!I:I) -> 38281.5 | G11: =AVERAGEIF(Продаж!E:E,Покупець_аналіз!A11,Продаж!I:I) -> 4785.1875
A12: 11 | B12: Кушнір | C12: Сергій | D12: 76 | E12: =COUNTIF(Продаж!E:E,Покупець_аналіз!A12) -> 8 | F12: =SUMIF(Продаж!E:E,A12,Продаж!I:I) -> 35833.08 | G12: =AVERAGEIF(Продаж!E:E,Покупець_аналіз!A12,Продаж!I:I) -> 4479.135
A13: 12 | B13: Білан | C13: Сергій | D13: 47 | E13: =COUNTIF(Продаж!E:E,Покупець_аналіз!A13) -> 5 | F13: =SUMIF(Продаж!E:E,A13,Продаж!I:I) -> 12573.22 | G13: =AVERAGEIF(Продаж!E:E,Покупець_аналіз!A13,Продаж!I:I) -> 2514.644
... A701: 700 | B701: Ткаченко | C701: Іван | D701: 46 | E701: =COUNTIF(Продаж!E:E,Покупець_аналіз!A701) -> 0 | F701: =SUMIF(Продаж!E:E,A701,Продаж!I:I) -> 0 | G701: =AVERAGEIF(Продаж!E:E,Покупець_аналіз!A701,Продаж!I:I) -> #DIV/0!

Sheet Аптека
A1: id_аптеки | B1: назва | C1: адреса | D1: місто | E1: Виручка по кожній аптеці
A2: 1 | B2: Аптека №1 | C2: вул. Коперника, 40 | D2: Рівне | E2: =SUMIF(Продаж!D:D,Аптека!A2,Продаж!I:I) -> 317960.48
A3: 2 | B3: Аптека №2 | C3: вул. Грушевського, 34 | D3: Київ | E3: =SUMIF(Продаж!D:D,Аптека!A3,Продаж!I:I) -> 451712.3
A4: 3 | B4: Аптека №3 | C4: вул. Степана Бандери, 109 | D4: Львів | E4: =SUMIF(Продаж!D:D,Аптека!A4,Продаж!I:I) -> 273372.05
A5: 4 | B5: Аптека №4 | C5: вул. Соборна, 86 | D5: Львів | E5: =SUMIF(Продаж!D:D,Аптека!A5,Продаж!I:I) -> 375106.1
A6: 5 | B6: Аптека №5 | C6: вул. Коперника, 8 | D6: Рівне | E6: =SUMIF(Продаж!D:D,Аптека!A6,Продаж!I:I) -> 371141.53
A7: 6 | B7: Аптека №6 | C7: вул. Зелена, 64 | D7: Миколаїв | E7: =SUMIF(Продаж!D:D,Аптека!A7,Продаж!I:I) -> 298967.78
A8: 7 | B8: Аптека №7 | C8: вул. Соборна, 24 | D8: Рівне | E8: =SUMIF(Продаж!D:D,Аптека!A8,Продаж!I:I) -> 410703.18
A9: 8 | B9: Аптека №8 | C9: вул. Миру, 42 | D9: Миколаїв | E9: =SUMIF(Продаж!D:D,Аптека!A9,Продаж!I:I) -> 317174.1
A10: 9 | B10: Аптека №9 | C10: вул. Грушевського, 82 | D10: Івано-Франківськ | E10: =SUMIF(Продаж!D:D,Аптека!A10,Продаж!I:I) -> 282129.25
A11: 10 | B11: Аптека №10 | C11: вул. Степана Бандери, 56 | D11: Київ | E11: =SUMIF(Продаж!D:D,Аптека!A11,Продаж!I:I) -> 299498.13
A12: 11 | B12: Аптека №11 | C12: вул. Незалежності, 81 | D12: Івано-Франківськ | E12: =SUMIF(Продаж!D:D,Аптека!A12,Продаж!I:I) -> 339766.09
A13: 12 | B13: Аптека №12 | C13: вул. Грушевського, 59 | D13: Тернопіль | E13: =SUMIF(Продаж!D:D,Аптека!A13,Продаж!I:I) -> 262488.23
... A61: 60 | B61: Аптека №60 | C61: вул. Грушевського, 2 | D61: Тернопіль | E61: =SUMIF(Продаж!D:D,Аптека!A61,Продаж!I:I) -> 361691.51

Sheet Покупець
A1: id_покупця | B1: прізвище | C1: ім'я | D1: по-батькові | E1: стать | F1: вік | G1: телефон
A2: 1 | B2: Бондар | C2: Тетяна | D2: Сергіївна | E2: Жінка | F2: 67 | G2: 617838922
A3: 2 | B3: Мельник | C3: Сергій | D3: Володимирович | E3: Чоловік | F3: 66 | G3: 556115058
A4: 3 | B4: Романюк | C4: Тетяна | D4: Сергіївна | E4: Жінка | F4: 84 | G4: 811369700
A5: 4 | B5: Степаненко | C5: Катерина | D5: Олегівна | E5: Жінка | F5: 48 | G5: 559880833
A6: 5 | B6: Кушнір | C6: Дмитро | D6: Петрович | E6: Чоловік | F6: 53 | G6: 920096360
A7: 6 | B7: Коваль | C7: Олександр | D7: Сергійович | E7: Чоловік | F7: 54 | G7: 826915543
A8: 7 | B8: Коваль | C8: Руслан | D8: Володимирович | E8: Чоловік | F8: 39 | G8: 907265034
A9: 8 | B9: Савчук | C9: Андрій | D9: Іванович | E9: Чоловік | F9: 78 | G9: 722380012
A10: 9 | B10: Шевченко | C10: Максим | D10: Петрович | E10: Чоловік | F10: 78 | G10: 593426394
A11: 10 | B11: Білан | C11: Софія | D11: Андріївна | E11: Жінка | F11: 71 | G11: 997031304
A12: 11 | B12: Кушнір | C12: Сергій | D12: Андрійович | E12: Чоловік | F12: 76 | G12: 806903190
A13: 12 | B13: Білан | C13: Сергій | D13: Сергійович | E13: Чоловік | F13: 47 | G13: 517811695
... A566: 565 | B566: Кравець | C566: Наталія | D566: Петрівна | E566: Жінка | F566: 61 | G566: 815160114
A567: 566 | B567: Гордієнко | C567: Тарас | D567: Володимирович | E567: Чоловік | F567: 58 | G567: 0699210556
A568: 567 | B568: Мельник | C568: Андрій | D568: Сергійович | E568: Чоловік | F568: 26 | G568: 0684302727
A569: 568 | B569: Лисенко | C569: Ірина | D569: Тарасівна | E569: Жінка | F569: 45 | G569: 0865354867
A570: 569 | B570: Олійник | C570: Сергій | D570: Романович | E570: Чоловік | F570: 35 | G570: 0849577002
A571: 570 | B571: Ткаченко | C571: Юрій | D571: Михайлович | E571: Чоловік | F571: 64 | G571: 0505930397
A572: 571 | B572: Шевченко | C572: Роман | D572: Володимирович | E572: Чоловік | F572: 52 | G572: 0698722580
A573: 572 | B573: Коваль | C573: Софія | D573: Петрівна | E573: Жінка | F573: 85 | G573: 0554449996
A574: 573 | B574: Ткаченко | C574: Володимир | D574: Романович | E574: Чоловік | F574: 36 | G574: 0893604828
A575: 574 | B575: Бондар | C575: Наталія | D575: Іванівна | E575: Жінка | F575: 57 | G575: 0991745130
A576: 575 | B576: Гордійчук | C576: Людмила | D576: Петрівна | E576: Жінка | F576: 43 | G576: 0985157063
A577: 576 | B577: Лисенко | C577: Юрій | D577: Олегович | E577: Чоловік | F577: 66 | G577: 0943432172
A578: 577 | B578: Бойко | C578: Людмила | D578: Сергіївна | E578: Жінка | F578: 45 | G578: 0892839615
... A701: 700 | B701: Ткаченко | C701: Іван | D701: Тарасович | E701: Чоловік | F701: 46 | G701: 0506764638

Sheet Працівник
A1: id_працівника | B1: прізвище | C1: ім'я | D1: по-батькові | E1: стать | F1: вік | G1: телефон
A2: 1 | B2: Петренко | C2: Софія | D2: Олександрівна | E2: Жінка | F2: 24 | G2: 606133930
A3: 2 | B3: Бондар | C3: Ігор | D3: Юріївна | E3: Чоловік | F3: 60 | G3: 608037017
A4: 3 | B4: Коваль | C4: Богдан | D4: Іванович | E4: Чоловік | F4: 28 | G4: 678972807
A5: 4 | B5: Бондар | C5: Софія | D5: Андріївна | E5: Жінка | F5: 59 | G5: 761054808
A6: 5 | B6: Мазур | C6: Оксана | D6: Іванович | E6: Жінка | F6: 28 | G6: 975332681
A7: 6 | B7: Бондар | C7: Олена | D7: Юрійович | E7: Жінка | F7: 54 | G7: 968913677
A8: 7 | B8: Коваль | C8: Юлія | D8: Ігорівна | E8: Жінка | F8: 52 | G8: 615752363
A9: 8 | B9: Петренко | C9: Софія | D9: Олегівна | E9: Жінка | F9: 48 | G9: 738713815
A10: 9 | B10: Петренко | C10: Володимир | D10: Богданівна | E10: Чоловік | F10: 36 | G10: 807058045
A11: 10 | B11: Іваненко | C11: Андрій | D11: Юрійович | E11: Чоловік | F11: 46 | G11: 898450221
A12: 11 | B12: Савчук | C12: Катерина | D12: Олегівна | E12: Жінка | F12: 57 | G12: 615107634
A13: 12 | B13: Коваль | C13: Олена | D13: Олександрівна | E13: Жінка | F13: 22 | G13: 939076454
... A401: 400 | B401: Шевченко | C401: Оксана | D401: Ігорівна | E401: Жінка | F401: 48 | G401: 855748482

Sheet Рецепт
A1: id_рецепту | B1: номер | C1: лікар | D1: дата
A2: 1 | B2: RX-000001 | C2: Д-р Руденко | D2: 45942
A3: 2 | B3: RX-000002 | C3: Д-р Михайленко | D3: 45957
A4: 3 | B4: RX-000003 | C4: Д-р Руденко | D4: 45326
A5: 4 | B5: RX-000004 | C5: Д-р Мушинський | D5: 45775
A6: 5 | B6: RX-000005 | C6: Д-р Муляр | D6: 45692
A7: 6 | B7: RX-000006 | C7: Д-р Снігур | D7: 45426
A8: 7 | B8: RX-000007 | C8: Д-р Орел | D8: 45745
A9: 8 | B9: RX-000008 | C9: Д-р Мельниченко | D9: 45707
A10: 9 | B10: RX-000009 | C10: Д-р Мазур | D10: 45405
A11: 10 | B11: RX-000010 | C11: Д-р Мушинський | D11: 45590
A12: 11 | B12: RX-000011 | C12: Д-р Мушинський | D12: 45809
A13: 12 | B13: RX-000012 | C13: Д-р Мазепа | D13: 45909
... A1301: 1300 | B1301: RX-001300 | C1301: Д-р Мельниченко | D1301: 45745

Sheet Чек
A1: id_чеку
A2: 1001
A3: 1002
A4: 1003
A5: 1004
A6: 1005
A7: 1006
A8: 1007
A9: 1008
A10: 1009
A11: 1010
A12: 1011
A13: 1012
... A5001: 6000

Sheet Чек_позиція
A1: id_позиції | B1: кількість | C1: id_товару | D1: id_чеку | E1: Ціна_товару | F1: Сума_позиції
A2: 1 | B2: 4 | C2: 7752 | D2: 1001 | E2: =VLOOKUP(Чек_позиція!C2,Товар!A:G,7,FALSE) -> 216.26 | F2: =B2*E2 -> 865.04
A3: 2 | B3: 4 | C3: 1965 | D3: 1001 | E3: =VLOOKUP(Чек_позиція!C3,Товар!A:G,7,FALSE) -> 666.19 | F3: =B3*E3 -> 2664.76
A4: 3 | B4: 1 | C4: 7454 | D4: 1001 | E4: =VLOOKUP(Чек_позиція!C4,Товар!A:G,7,FALSE) -> 619.46 | F4: =B4*E4 -> 619.46
A5: 4 | B5: 4 | C5: 9708 | D5: 1002 | E5: =VLOOKUP(Чек_позиція!C5,Товар!A:G,7,FALSE) -> 646.39 | F5: =B5*E5 -> 2585.56
A6: 5 | B6: 2 | C6: 8566 | D6: 1002 | E6: =VLOOKUP(Чек_позиція!C6,Товар!A:G,7,FALSE) -> 337.17 | F6: =B6*E6 -> 674.34
A7: 6 | B7: 2 | C7: 8062 | D7: 1002 | E7: =VLOOKUP(Чек_позиція!C7,Товар!A:G,7,FALSE) -> 768.19 | F7: =B7*E7 -> 1536.38
A8: 7 | B8: 1 | C8: 214 | D8: 1002 | E8: =VLOOKUP(Чек_позиція!C8,Товар!A:G,7,FALSE) -> 674.05 | F8: =B8*E8 -> 674.05
A9: 8 | B9: 4 | C9: 4717 | D9: 1002 | E9: =VLOOKUP(Чек_позиція!C9,Товар!A:G,7,FALSE) -> 353.93 | F9: =B9*E9 -> 1415.72
A10: 9 | B10: 3 | C10: 934 | D10: 1003 | E10: =VLOOKUP(Чек_позиція!C10,Товар!A:G,7,FALSE) -> 861.54 | F10: =B10*E10 -> 2584.62
A11: 10 | B11: 1 | C11: 9591 | D11: 1003 | E11: =VLOOKUP(Чек_позиція!C11,Товар!A:G,7,FALSE) -> 264.22 | F11: =B11*E11 -> 264.22
A12: 11 | B12: 3 | C12: 7527 | D12: 1004 | E12: =VLOOKUP(Чек_позиція!C12,Товар!A:G,7,FALSE) -> 99.78 | F12: =B12*E12 -> 299.34
A13: 12 | B13: 4 | C13: 939 | D13: 1004 | E13: =VLOOKUP(Чек_позиція!C13,Товар!A:G,7,FALSE) -> 125.16 | F13: =B13*E13 -> 500.64
... A14907: 14906 | B14907: 4 | C14907: 5646 | D14907: 6000 | E14907: =VLOOKUP(Чек_позиція!C14907,Товар!A:G,7,FALSE) -> 326.1 | F14907: =B14907*E14907 -> 1304.4

Sheet Товар
A1: id_товару | B1: назва | C1: категорія | D1: виробник | E1: форма | F1: дозування | G1: ціна | H1: id_постачальника
A2: 1 | B2: Панкреатин Плюс | C2: Антисептики | D2: Darnitsa | E2: ампули | F2: 10 мл | G2: 551.13 | H2: 172
A3: 2 | B3: Ібупрофен | C3: Протиалергічні | D3: Berlin-Chemie | E3: гель | F3: 200 мл | G3: 86.82 | H3: 74
A4: 3 | B4: Аскорбінова кислота Макс | C4: Протиалергічні | D4: Arterium | E4: ампули | F4: 10 мл | G4: 233.59 | H4: 169
A5: 4 | B5: Амброксол Плюс | C5: Вітаміни | D5: Bayer | E5: суспензія | F5: 250 мг | G5: 144.55 | H5: 72
A6: 5 | B6: Аскорбінова кислота Плюс | C6: Дитячі препарати | D6: Gedeon Richter | E6: суспензія | F6: 20 мл | G6: 598.35 | H6: 165
A7: 6 | B7: Ринопронт Форте | C7: Протизастудні | D7: Berlin-Chemie | E7: сироп | F7: 5 мг | G7: 204.18 | H7: 180
A8: 7 | B8: Панкреатин Макс | C8: Протиалергічні | D8: Bayer | E8: таблетки | F8: 25 мг | G8: 831.58 | H8: 145
A9: 8 | B9: Кардіомагніл | C9: Вітаміни | D9: Zentiva | E9: таблетки | F9: 10 мг | G9: 718.96 | H9: 56
A10: 9 | B10: Лоратадин | C10: Імуномодулятори | D10: Bayer | E10: краплі | F10: 250 мг | G10: 323.59 | H10: 84
A11: 10 | B11: Панкреатин Форте | C11: Знеболюючі | D11: Zentiva | E11: краплі | F11: 20 мл | G11: 85.28 | H11: 21
A12: 11 | B12: Но-шпа | C12: Очні краплі | D12: Gedeon Richter | E12: розчин | F12: 20 мл | G12: 442.26 | H12: 70
A13: 12 | B13: Цитрамон Форте | C13: Протиалергічні | D13: Gedeon Richter | E13: капсули | F13: 100 мг | G13: 657.18 | H13: 152
... A10001: 10000 | B10001: Но-шпа Форте | C10001: Антибіотики | D10001: Gedeon Richter | E10001: капсули | F10001: 500 мг | G10001: 826.24 | H10001: 134

Sheet Постачальник
A1: id_постачальника | B1: назва | C1: контакти | D1: код_ЄДРПОУ
A2: 1 | B2: ПрАТ «ФармЛайф Груп» | C2: farmlaif1@farmalogic.ua | D2: 49997825
A3: 2 | B3: ТОВ «ФармТрейд» | C3: farmtreid2@medsup.ua | D3: 45980162
A4: 3 | B4: ПрАТ «ФармЛайн» | C4: farmlain3@medsup.ua | D4: 32040961
A5: 4 | B5: ТОВ «Аптека-Плюс» | C5: apteka.plius4@farmalogic.ua | D5: 46450692
A6: 5 | B6: ПрАТ «ФармПартнер Вінниця» | C6: farmpartner5@biofarm.ua | D6: 36951047
A7: 6 | B7: ПрАТ «МедАльянс» | C7: medalians6@pharmtrade.ua | D7: 44303369
A8: 7 | B8: ПрАТ «ФармЛайн Груп» | C8: farmlain7@pharmtrade.ua | D8: 34854922
A9: 8 | B9: ТОВ «ФармСвіт» | C9: farmsvit8@medlogist.ua | D9: 45369356
A10: 9 | B10: ТОВ «МедСвіт Груп» | C10: medsvit9@pharm.ua | D10: 43694096
A11: 10 | B11: ПрАТ «ФармПрофі» | C11: farmprofi10@medlogist.ua | D11: 36737555
A12: 11 | B12: ТОВ «ФармКом Груп» | C12: farmkom11@farmalogic.ua | D12: 32465939
A13: 12 | B13: ПрАТ «Фарматика Київ» | C13: farmatyka12@aptekaopt.ua | D13: 43040790
... A201: 200 | B201: ПрАТ «ФармТрейд» | C201: farmtreid200@pharm.ua | D201: 34253310

Sheet Постачальник_аналіз
A1: {=_xlfn.UNIQUE(Товар!H:H)} -> id_постачальника | B1: к_сть_товарів_постач
A2: 172 | B2: =COUNTIF(Товар!H:H,Постачальник_аналіз!A2) -> 54 | C2: =AVERAGEIF(Товар!H:H,Постачальник_аналіз!A2,Товар!G:G) -> 470.59426
A3: 74 | B3: =COUNTIF(Товар!H:H,Постачальник_аналіз!A3) -> 45
A4: 169 | B4: =COUNTIF(Товар!H:H,Постачальник_аналіз!A4) -> 60
A5: 72 | B5: =COUNTIF(Товар!H:H,Постачальник_аналіз!A5) -> 65
A6: 165 | B6: =COUNTIF(Товар!H:H,Постачальник_аналіз!A6) -> 47
A7: 180 | B7: =COUNTIF(Товар!H:H,Постачальник_аналіз!A7) -> 53
A8: 145 | B8: =COUNTIF(Товар!H:H,Постачальник_аналіз!A8) -> 42
A9: 56 | B9: =COUNTIF(Товар!H:H,Постачальник_аналіз!A9) -> 49
A10: 84 | B10: =COUNTIF(Товар!H:H,Постачальник_аналіз!A10) -> 63
A11: 21 | B11: =COUNTIF(Товар!H:H,Постачальник_аналіз!A11) -> 57
A12: 70 | B12: =COUNTIF(Товар!H:H,Постачальник_аналіз!A12) -> 50
A13: 152 | B13: =COUNTIF(Товар!H:H,Постачальник_аналіз!A13) -> 64
A14: 53 | B14: =COUNTIF(Товар!H:H,Постачальник_аналіз!A14) -> 61
... A202: 0 | B202: =COUNTIF(Товар!H:H,Постачальник_аналіз!A202) -> 0

Sheet Робота
A1: id_роботи | B1: id_працівника | C1: дата | D1: відпрацьовано_годин
A2: 1 | B2: 357 | C2: 45711 | D2: 8
A3: 2 | B3: 252 | C3: 45745 | D3: 7
A4: 3 | B4: 353 | C4: 45713 | D4: 8
A5: 4 | B5: 100 | C5: 45721 | D5: 6
A6: 5 | B6: 83 | C6: 45762 | D6: 10
A7: 6 | B7: 19 | C7: 45753 | D7: 10
A8: 7 | B8: 254 | C8: 45665 | D8: 7
A9: 8 | B9: 251 | C9: 45697 | D9: 7
A10: 9 | B10: 398 | C10: 45802 | D10: 9
A11: 10 | B11: 370 | C11: 45800 | D11: 6
A12: 11 | B12: 369 | C12: 45813 | D12: 9
A13: 12 | B13: 95 | C13: 45756 | D13: 6
... A11001: 11000 | B11001: 215 | C11001: 45737 | D11001: 6

Sheet Зведення_1
A1: Кількість продажів | B1: Кількість аптек | C1: Кількість покупців | D1: Кількість товарів
A2: =COUNT(Продаж!A:A) -> 5000 | B2: =COUNT(Аптека!A:A) -> 60 | C2: =COUNT(Покупець!A:A) -> 700 | D2: =COUNT(Товар!A:A) -> 10000
A5: Кількість продажів | B5: Готівка | C5: Карта
B6: =COUNTIF(Продаж!$C:$C,B$5) -> 2062 | C6: =COUNTIF(Продаж!$C:$C,C$5) -> 2938
B9: Без карти Аптеки | C9: З картою аптеки
B10: =COUNTIF(Продаж!E2:E5001,"") -> 1472 | C10: =COUNT(Продаж!E:E) -> 3528
